<?xml version="1.0" encoding="utf-8"?>
<!-- This URDF was automatically created by SolidWorks to URDF Exporter! Originally created by Stephen Brawner (brawner@gmail.com) 
     Commit Version: 1.6.0-4-g7f85cfe  Build Version: 1.6.7995.38578
     For more information, please see http://wiki.ros.org/sw_urdf_exporter -->
<robot
  name="two_finger_gripper">
  <link
    name="base_link">
    <inertial>
      <origin
        xyz="8.81354273374553E-09 -4.22886858600738E-07 -1.70898026224046E-08"
        rpy="0 0 0" />
      <mass
        value="0.187618707682634" />
      <inertia
        ixx="0.000403340846571004"
        ixy="1.15856180736469E-10"
        ixz="9.14631350659822E-12"
        iyy="1.77436072317056E-05"
        iyz="-2.20966031792127E-10"
        izz="0.000392747111510324" />
    </inertial>
    <visual>
      <origin
        xyz="0 0 0"
        rpy="0 0 0" />
      <geometry>
        <mesh
          filename="package://two_finger_gripper/meshes/base_link.STL" />
      </geometry>
      <material
        name="">
        <color
          rgba="0.866666666666667 0.909803921568627 1 1" />
      </material>
    </visual>
    <collision>
      <origin
        xyz="0 0 0"
        rpy="0 0 0" />
      <geometry>
        <mesh
          filename="package://two_finger_gripper/meshes/base_link.STL" />
      </geometry>
    </collision>
  </link>
  <link
    name="right_side">
    <inertial>
      <origin
        xyz="2.08166817117217E-17 2.8652322981988E-08 0.00999999876379252"
        rpy="1.5708 0 -1.5828" />
      <mass
        value="0.00400455448945673" />
      <inertia
        ixx="1.92052268591215E-07"
        ixy="8.65203978677214E-13"
        ixz="-4.99818541676623E-14"
        iyy="2.10355619255483E-07"
        iyz="-1.41858307695259E-19"
        izz="2.97791048750068E-07" />
    </inertial>
    <visual>
      <origin
        xyz="0 0 0"
        rpy="1.5708 0 -1.5828" />
      <geometry>
        <mesh
          filename="package://two_finger_gripper/meshes/right_side.STL" />
      </geometry>
      <material
        name="">
        <color
          rgba="0.792156862745098 0.819607843137255 0.933333333333333 1" />
      </material>
    </visual>
    <collision>
      <origin
        xyz="0 0 0"
        rpy="1.5708 0 -1.5828" />
      <geometry>
        <mesh
          filename="package://two_finger_gripper/meshes/right_side.STL" />
      </geometry>
    </collision>
  </link>
  <joint
    name="right_base_joint"
    type="revolute">
    <origin
      xyz="0 0.06005 0.015"
      rpy="0 0 0" />
    <parent
      link="base_link" />
    <child
      link="right_side" />
    <axis
      xyz="0 0 1" />
    <limit
      lower="-0.5235"
      upper="0.5235"
      effort="10.0"
      velocity="4.0" />
  </joint>
  <link
    name="right_side_pitch">
    <inertial>
      <origin
        xyz="0 2.86523228808862E-08 0.00999999876379255"
        rpy="0 0 -1.577" />
      <mass
        value="0.00400455448945672" />
      <inertia
        ixx="1.92052268591215E-07"
        ixy="8.65203978749533E-13"
        ixz="-4.99818541784156E-14"
        iyy="2.10355619255482E-07"
        iyz="-1.41830818818275E-19"
        izz="2.97791048750067E-07" />
    </inertial>
    <visual>
      <origin
        xyz="-0.01 0 0"
        rpy="0 0 -1.577" />
      <geometry>
        <mesh
          filename="package://two_finger_gripper/meshes/right_side.STL" />
      </geometry>
      <material
        name="">
        <color
          rgba="0.792156862745098 0.819607843137255 0.933333333333333 1" />
      </material>
    </visual>
    <collision>
      <origin
        xyz="0 0 0"
        rpy="0 0 -1.577" />
      <geometry>
        <mesh
          filename="package://two_finger_gripper/meshes/right_side.STL" />
      </geometry>
    </collision>
  </link>
  <joint
    name="right_base_pitch_joint"
    type="revolute">
    <origin
      xyz="0 0 0.025"
      rpy="0 0 0" />
    <parent
      link="right_side" />
    <child
      link="right_side_pitch" />
    <axis
      xyz="0 1 0" />
    <limit
      lower="-0.5235"
      upper="0.5235"
      effort="10.0"
      velocity="4.0" />
  </joint>
  <link
    name="R1">
    <inertial>
      <origin
        xyz="1.26851654180804E-17 2.28983498828939E-16 0.0350000000000001"
        rpy="1.57 0 0" />
      <mass
        value="0.0498429795113518" />
      <inertia
        ixx="2.68907785888968E-05"
        ixy="-8.23210145612773E-21"
        ixz="1.45583787809333E-22"
        iyy="2.31661213105638E-06"
        iyz="5.44727756250782E-12"
        izz="2.57685006174922E-05" />
    </inertial>
    <visual>
      <origin
        xyz="0 0 0"
        rpy="1.57 0 0" />
      <geometry>
        <mesh
          filename="package://two_finger_gripper/meshes/R1.STL" />
      </geometry>
      <material
        name="">
        <color
          rgba="0.866666666666667 0.909803921568627 1 1" />
      </material>
    </visual>
    <collision>
      <origin
        xyz="0 0 0"
        rpy="1.57 0 0" />
      <geometry>
        <mesh
          filename="package://two_finger_gripper/meshes/R1.STL" />
      </geometry>
    </collision>
  </link>
  <joint
    name="R1_joint"
    type="revolute">
    <origin
      xyz="0 0.0 0.009"
      rpy="0 0 0" />
    <parent
      link="right_side_pitch" />
    <child
      link="R1" />
    <axis
      xyz="1 0 0" />
    <limit
      lower="-1.57"
      upper="0.5235"
      effort="10.0"
      velocity="4.0" />
  </joint>
  <link
    name="R2">
    <inertial>
      <origin
        xyz="-4.56796454828545E-10 0 0.0296521459141245"
        rpy="1.4 0 0" />
      <mass
        value="0.0433629505400265" />
      <inertia
        ixx="1.82012341198528E-05"
        ixy="4.22211999752767E-21"
        ixz="7.54388718648361E-22"
        iyy="2.37316309026694E-06"
        iyz="-2.28036734065714E-06"
        izz="1.68668845317301E-05" />
    </inertial>
    <visual>
      <origin
        xyz="0 0 0"
        rpy="1.4 0 0" />
      <geometry>
        <mesh
          filename="package://two_finger_gripper/meshes/R2.STL" />
      </geometry>
      <material
        name="">
        <color
          rgba="0.866666666666667 0.909803921568627 1 1" />
      </material>
    </visual>
    <collision>
      <origin
        xyz="0 0 0"
        rpy="1.4 0 0" />
      <geometry>
        <mesh
          filename="package://two_finger_gripper/meshes/R2.STL" />
      </geometry>
    </collision>
  </link>
  <joint
    name="R2_joint"
    type="revolute">
    <origin
      xyz="0 0.0 0.07"
      rpy="0 0 0" />
    <parent
      link="R1" />
    <child
      link="R2" />
    <axis
      xyz="1 0 0" />
    <limit
      lower="-0.5235"
      upper="2"
      effort="10.0"
      velocity="4.0" />
  </joint>
  <link
    name="R3">
    <inertial>
      <origin
        xyz="-1.69162753791731E-10 0 0.0283253438069827"
        rpy="1.25 0 0" />
      <mass
        value="0.0429708583079173" />
      <inertia
        ixx="1.75254049269463E-05"
        ixy="-1.65519553713868E-13"
        ixz="-2.03891445606294E-13"
        iyy="3.20880478988122E-06"
        iyz="-4.13484726157431E-06"
        izz="1.53469520450817E-05" />
    </inertial>
    <visual>
      <origin
        xyz="0 0.001 0"
        rpy="1.25 0 0" />
      <geometry>
        <mesh
          filename="package://two_finger_gripper/meshes/R3.STL" />
      </geometry>
      <material
        name="">
        <color
          rgba="0.866666666666667 0.909803921568627 1 1" />
      </material>
    </visual>
    <collision>
      <origin
        xyz="0 0.001 0"
        rpy="1.25 0 0" />
      <geometry>
        <mesh
          filename="package://two_finger_gripper/meshes/R3.STL" />
      </geometry>
    </collision>
  </link>
  <joint
    name="R3_joint"
    type="revolute">
    <origin
      xyz="0 0 0.06"
      rpy="0 0 0" />
    <parent
      link="R2" />
    <child
      link="R3" />
    <axis
      xyz="1 0 0" />
    <limit
      lower="-0.5235"
      upper="1.57"
      effort="10.0"
      velocity="4.0" />
  </joint>
  <link
    name="left_side">
    <inertial>
      <origin
        xyz="0 2.86523228808862E-08 0.00999999876379255"
        rpy="1.5708 0 -1.577" />
      <mass
        value="0.00400455448945672" />
      <inertia
        ixx="1.92052268591215E-07"
        ixy="8.65203978749533E-13"
        ixz="-4.99818541784156E-14"
        iyy="2.10355619255482E-07"
        iyz="-1.41830818818275E-19"
        izz="2.97791048750067E-07" />
    </inertial>
    <visual>
      <origin
        xyz="0 0 0"
        rpy="1.5708 0 -1.577" />
      <geometry>
        <mesh
          filename="package://two_finger_gripper/meshes/left_side.STL" />
      </geometry>
      <material
        name="">
        <color
          rgba="0.792156862745098 0.819607843137255 0.933333333333333 1" />
      </material>
    </visual>
    <collision>
      <origin
        xyz="0 0 0"
        rpy="1.5708 0 -1.577" />
      <geometry>
        <mesh
          filename="package://two_finger_gripper/meshes/left_side.STL" />
      </geometry>
    </collision>
  </link>
  <joint
    name="left_base_yaw_joint"
    type="revolute">
    <origin
      xyz="0 -0.060046 0.015"
      rpy="0 0 0" />
    <parent
      link="base_link" />
    <child
      link="left_side" />
    <axis
      xyz="0 0 1" />
    <limit
      lower="-0.5235"
      upper="0.5235"
      effort="10.0"
      velocity="4.0" />
  </joint>
  <link
    name="left_side_pitch">
    <inertial>
      <origin
        xyz="0 2.86523228808862E-08 0.00999999876379255"
        rpy="0 0 -1.577" />
      <mass
        value="0.00400455448945672" />
      <inertia
        ixx="1.92052268591215E-07"
        ixy="8.65203978749533E-13"
        ixz="-4.99818541784156E-14"
        iyy="2.10355619255482E-07"
        iyz="-1.41830818818275E-19"
        izz="2.97791048750067E-07" />
    </inertial>
    <visual>
      <origin
        xyz="-0.01 0 0"
        rpy="0 0 -1.577" />
      <geometry>
        <mesh
          filename="package://two_finger_gripper/meshes/left_side.STL" />
      </geometry>
      <material
        name="">
        <color
          rgba="0.792156862745098 0.819607843137255 0.933333333333333 1" />
      </material>
    </visual>
    <collision>
      <origin
        xyz="0 0 0"
        rpy="0 0 -1.577" />
      <geometry>
        <mesh
          filename="package://two_finger_gripper/meshes/left_side.STL" />
      </geometry>
    </collision>
  </link>
  <joint
    name="left_base_pitch_joint"
    type="revolute">
    <origin
      xyz="0 0 0.025"
      rpy="0 0 0" />
    <parent
      link="left_side" />
    <child
      link="left_side_pitch" />
    <axis
      xyz="0 1 0" />
    <limit
      lower="-0.5235"
      upper="0.5235"
      effort="10.0"
      velocity="4.0" />
  </joint>
  <link
    name="L1">
    <inertial>
      <origin
        xyz="-4.56040182505134E-10 0 0.0350000000000008"
        rpy="1.57 0 0" />
      <mass
        value="0.0498429374208329" />
      <inertia
        ixx="2.68907345933772E-05"
        ixy="3.69278240862048E-20"
        ixz="3.90429249125029E-22"
        iyy="2.31660840247375E-06"
        iyz="1.72037113675422E-11"
        izz="2.57684595575646E-05" />
    </inertial>
    <visual>
      <origin
        xyz="0 0 0"
        rpy="1.57 0 0" />
      <geometry>
        <mesh
          filename="package://two_finger_gripper/meshes/L1.STL" />
      </geometry>
      <material
        name="">
        <color
          rgba="0.866666666666667 0.909803921568627 1 1" />
      </material>
    </visual>
    <collision>
      <origin
        xyz="0 0 0"
        rpy="1.57 0 0" />
      <geometry>
        <mesh
          filename="package://two_finger_gripper/meshes/L1.STL" />
      </geometry>
    </collision>
  </link>
  <joint
    name="L1_joint"
    type="revolute">
    <origin
      xyz="0 0 0.009"
      rpy="0 0 0" />
    <parent
      link="left_side_pitch" />
    <child
      link="L1" />
    <axis
      xyz="1 0 0" />
    <limit
      lower="-0.5235"
      upper="1.57"
      effort="10.0"
      velocity="4.0" />
  </joint>
  <link
    name="L2">
    <inertial>
      <origin
        xyz="0 0 0.035"
        rpy="1.57 0 0" />
      <mass
        value="0.0433629505400265" />
      <inertia
        ixx="1.82012341198528E-05"
        ixy="1.26644453709166E-20"
        ixz="-1.05879118406788E-22"
        iyy="2.02284897334824E-06"
        iyz="1.38370400837543E-11"
        izz="1.72171986486488E-05" />
    </inertial>
    <visual>
      <origin
        xyz="0 0 0"
        rpy="1.57 0 0" />
      <geometry>
        <mesh
          filename="package://two_finger_gripper/meshes/L2.STL" />
      </geometry>
      <material
        name="">
        <color
          rgba="0.866666666666667 0.909803921568627 1 1" />
      </material>
    </visual>
    <collision>
      <origin
        xyz="0 0 0"
        rpy="1.57 0 0" />
      <geometry>
        <mesh
          filename="package://two_finger_gripper/meshes/L2.STL" />
      </geometry>
    </collision>
  </link>
  <joint
    name="L2_joint"
    type="revolute">
    <origin
      xyz="0 0 0.07"
      rpy="0 0 0" />
    <parent
      link="L1" />
    <child
      link="L2" />
    <axis
      xyz="1 0 0" />
    <limit
      lower="-2"
      upper="1.57"
      effort="10.0"
      velocity="4.0" />
  </joint>
  <link
    name="L3">
    <inertial>
      <origin
        xyz="-2.66025734427244E-10 0 0.029"
        rpy="1.57 0 0" />
      <mass
        value="0.0429708569563452" />
      <inertia
        ixx="1.75254039654221E-05"
        ixy="-3.3850578916699E-13"
        ixz="-1.41606523806871E-13"
        iyy="1.93413163301078E-06"
        iyz="6.17860438572964E-12"
        izz="1.66216242182399E-05" />
    </inertial>
    <visual>
      <origin
        xyz="0 0 0"
        rpy="1.57 0 0" />
      <geometry>
        <mesh
          filename="package://two_finger_gripper/meshes/L3.STL" />
      </geometry>
      <material
        name="">
        <color
          rgba="0.866666666666667 0.909803921568627 1 1" />
      </material>
    </visual>
    <collision>
      <origin
        xyz="0 0 0"
        rpy="1.57 0 0" />
      <geometry>
        <mesh
          filename="package://two_finger_gripper/meshes/L3.STL" />
      </geometry>
    </collision>
  </link>
  <joint
    name="L3_joint"
    type="revolute">
    <origin
      xyz="0 0 0.06"
      rpy="0 0 0" />
    <parent
      link="L2" />
    <child
      link="L3" />
    <axis
      xyz="1 0 0" />
    <limit
      lower="-1.57"
      upper="0.5235"
      effort="10.0"
      velocity="4.0" />
  </joint>
</robot>