<?xml version="1.0" encoding="utf-8"?>
<!-- This URDF was automatically created by SolidWorks to URDF Exporter! Originally created by Stephen Brawner (brawner@gmail.com) 
     Commit Version: 1.6.0-4-g7f85cfe  Build Version: 1.6.7995.38578
     For more information, please see http://wiki.ros.org/sw_urdf_exporter -->
<robot
  name="two_link_manipulator">
  <link
    name="palm">
    <inertial>
      <origin
        xyz="0.67078 0.88478 1.3084"
        rpy="0 0 0" />
      <mass
        value="0.18762" />
      <inertia
        ixx="1.7744E-05"
        ixy="-2.2097E-10"
        ixz="1.1434E-10"
        iyy="0.00039275"
        iyz="9.4556E-12"
        izz="0.00040334" />
    </inertial>
    <visual>
      <origin
        xyz="0 0 0"
        rpy="0 0 0" />
      <geometry>
        <mesh
          filename="meshes_obj/palm.obj" />
      </geometry>
      <material
        name="">
        <color
          rgba="0.86667 0.9098 1 1" />
      </material>
    </visual>
    <collision>
      <origin
        xyz="0 0 0"
        rpy="0 0 0" />
      <geometry>
        <mesh
          filename="meshes_obj/palm.obj" />
      </geometry>
    </collision>
  </link>
  <link
    name="Left_base">
    <inertial>
      <origin
        xyz="0 0.01 2.8652E-08"
        rpy="0 0 0" />
      <mass
        value="0.0040046" />
      <inertia
        ixx="1.9205E-07"
        ixy="8.652E-13"
        ixz="-4.9982E-14"
        iyy="2.1036E-07"
        iyz="-1.4204E-19"
        izz="2.9779E-07" />
    </inertial>
    <visual>
      <origin
        xyz="0 0 0"
        rpy="0 0 0" />
      <geometry>
        <mesh
          filename="meshes_obj/Left_base.obj" />
      </geometry>
      <material
        name="">
        <color
          rgba="0.79216 0.81961 0.93333 1" />
      </material>
    </visual>
    <collision>
      <origin
        xyz="0 0 0"
        rpy="0 0 0" />
      <geometry>
        <mesh
          filename="meshes_obj/Left_base.obj" />
      </geometry>
    </collision>
  </link>
  <joint
    name="joint1"
    type="revolute">
    <origin
      xyz="0.61073 -1.3084 0.89978"
      rpy="1.5708 0 -0.77764" />
    <parent
      link="palm" />
    <child
      link="Left_base" />
    <axis
      xyz="0 1 0" />
    <limit
      lower="-1.57"
      upper="1.57"
      effort="5"
      velocity="2" />
  </joint>
  <link
    name="LL1">
    <inertial>
      <origin
        xyz="-0.035 1.2879E-14 2.2204E-16"
        rpy="0 0 0" />
      <mass
        value="0.049843" />
      <inertia
        ixx="2.3166E-06"
        ixy="-5.4473E-12"
        ixz="-1.5686E-19"
        iyy="2.5769E-05"
        iyz="6.7763E-21"
        izz="2.6891E-05" />
    </inertial>
    <visual>
      <origin
        xyz="0 0 0"
        rpy="0 0 0" />
      <geometry>
        <mesh
          filename="meshes_obj/LL1.obj" />
      </geometry>
      <material
        name="">
        <color
          rgba="0.86667 0.9098 1 1" />
      </material>
    </visual>
    <collision>
      <origin
        xyz="0 0 0"
        rpy="0 0 0" />
      <geometry>
        <mesh
          filename="meshes_obj/LL1.obj" />
      </geometry>
    </collision>
  </link>
  <joint
    name="joint2"
    type="revolute">
    <origin
      xyz="0 0.01 0"
      rpy="0 0 -0.66305" />
    <parent
      link="Left_base" />
    <child
      link="LL1" />
    <axis
      xyz="0 0 1" />
    <limit
      lower="-1.57"
      upper="1.57"
      effort="5"
      velocity="2" />
  </joint>
  <link
    name="LL2">
    <inertial>
      <origin
        xyz="0.03 9.4369E-15 4.568E-10"
        rpy="0 0 0" />
      <mass
        value="0.043363" />
      <inertia
        ixx="2.0228E-06"
        ixy="-1.3837E-11"
        ixz="-1.9439E-19"
        iyy="1.7217E-05"
        iyz="-4.0234E-21"
        izz="1.8201E-05" />
    </inertial>
    <visual>
      <origin
        xyz="0 0 0"
        rpy="0 0 0" />
      <geometry>
        <mesh
          filename="meshes_obj/LL2.obj" />
      </geometry>
      <material
        name="">
        <color
          rgba="0.86667 0.9098 1 1" />
      </material>
    </visual>
    <collision>
      <origin
        xyz="0 0 0"
        rpy="0 0 0" />
      <geometry>
        <mesh
          filename="meshes_obj/LL2.obj" />
      </geometry>
    </collision>
  </link>
  <joint
    name="joint3"
    type="revolute">
    <origin
      xyz="-0.07 0 0"
      rpy="0 0 0.95183" />
    <parent
      link="LL1" />
    <child
      link="LL2" />
    <axis
      xyz="0 0 1" />
    <limit
      lower="-1.57"
      upper="1.57"
      effort="5"
      velocity="2" />
  </joint>
  <link
    name="LL3">
    <inertial>
      <origin
        xyz="0.029641 -6.7376E-09 3.9692E-09"
        rpy="0 0 0" />
      <mass
        value="0.042971" />
      <inertia
        ixx="1.9341E-06"
        ixy="-7.0439E-12"
        ixz="4.8188E-12"
        iyy="1.6622E-05"
        iyz="-8.3066E-14"
        izz="1.7525E-05" />
    </inertial>
    <visual>
      <origin
        xyz="0 0 0"
        rpy="0 0 0" />
      <geometry>
        <mesh
          filename="meshes_obj/LL3.obj" />
      </geometry>
      <material
        name="">
        <color
          rgba="0.86667 0.9098 1 1" />
      </material>
    </visual>
    <collision>
      <origin
        xyz="0 0 0"
        rpy="0 0 0" />
      <geometry>
        <mesh
          filename="meshes_obj/LL3.obj" />
      </geometry>
    </collision>
  </link>
  <joint
    name="joint4"
    type="revolute">
    <origin
      xyz="0.06 0 0"
      rpy="0 0 0.91379" />
    <parent
      link="LL2" />
    <child
      link="LL3" />
    <axis
      xyz="0 0 1" />
    <limit
      lower="-1.57"
      upper="1.57"
      effort="5"
      velocity="2" />
  </joint>
  <link
    name="Right_base">
    <inertial>
      <origin
        xyz="0 0.01 2.8652E-08"
        rpy="0 0 0" />
      <mass
        value="0.0040046" />
      <inertia
        ixx="1.9205E-07"
        ixy="8.652E-13"
        ixz="-4.9982E-14"
        iyy="2.1036E-07"
        iyz="-1.4181E-19"
        izz="2.9779E-07" />
    </inertial>
    <visual>
      <origin
        xyz="0 0 0"
        rpy="0 0 0" />
      <geometry>
        <mesh
          filename="meshes_obj/Right_base.obj" />
      </geometry>
      <material
        name="">
        <color
          rgba="0.79216 0.81961 0.93333 1" />
      </material>
    </visual>
    <collision>
      <origin
        xyz="0 0 0"
        rpy="0 0 0" />
      <geometry>
        <mesh
          filename="meshes_obj/Right_base.obj" />
      </geometry>
    </collision>
  </link>
  <joint
    name="joint5"
    type="revolute">
    <origin
      xyz="0.73083 -1.3084 0.89978"
      rpy="1.5708 0 2.9852" />
    <parent
      link="palm" />
    <child
      link="Right_base" />
    <axis
      xyz="0 1 0" />
    <limit
      lower="-1.57"
      upper="1.57"
      effort="5"
      velocity="2" />
  </joint>
  <link
    name="RL1">
    <inertial>
      <origin
        xyz="0.035 5.6621E-15 4.5604E-10"
        rpy="0 0 0" />
      <mass
        value="0.049843" />
      <inertia
        ixx="2.3166E-06"
        ixy="-1.7204E-11"
        ixz="-4.0712E-19"
        iyy="2.5768E-05"
        iyz="5.0822E-21"
        izz="2.6891E-05" />
    </inertial>
    <visual>
      <origin
        xyz="0 0 0"
        rpy="0 0 0" />
      <geometry>
        <mesh
          filename="meshes_obj/RL1.obj" />
      </geometry>
      <material
        name="">
        <color
          rgba="0.86667 0.9098 1 1" />
      </material>
    </visual>
    <collision>
      <origin
        xyz="0 0 0"
        rpy="0 0 0" />
      <geometry>
        <mesh
          filename="meshes_obj/RL1.obj" />
      </geometry>
    </collision>
  </link>
  <joint
    name="joint6"
    type="revolute">
    <origin
      xyz="0 0.01 0"
      rpy="0 0 1.9755" />
    <parent
      link="Right_base" />
    <child
      link="RL1" />
    <axis
      xyz="0 0 1" />
    <limit
      lower="-1.57"
      upper="1.57"
      effort="5"
      velocity="2" />
  </joint>
  <link
    name="RL2">
    <inertial>
      <origin
        xyz="0.03 0 4.568E-10"
        rpy="0 0 0" />
      <mass
        value="0.043363" />
      <inertia
        ixx="2.0228E-06"
        ixy="-1.3837E-11"
        ixz="-1.9812E-19"
        iyy="1.7217E-05"
        iyz="1.3553E-20"
        izz="1.8201E-05" />
    </inertial>
    <visual>
      <origin
        xyz="0 0 0"
        rpy="0 0 0" />
      <geometry>
        <mesh
          filename="meshes_obj/RL2.obj" />
      </geometry>
      <material
        name="">
        <color
          rgba="0.86667 0.9098 1 1" />
      </material>
    </visual>
    <collision>
      <origin
        xyz="0 0 0"
        rpy="0 0 0" />
      <geometry>
        <mesh
          filename="meshes_obj/RL2.obj" />
      </geometry>
    </collision>
  </link>
  <joint
    name="joint7"
    type="revolute">
    <origin
      xyz="0.07 0 0"
      rpy="0 0 -0.77973" />
    <parent
      link="RL1" />
    <child
      link="RL2" />
    <axis
      xyz="0 0 1" />
    <limit
      lower="-1.57"
      upper="1.57"
      effort="5"
      velocity="2" />
  </joint>
  <link
    name="RL3">
    <inertial>
      <origin
        xyz="0.029641 -5.9431E-09 2.6922E-10"
        rpy="0 0 0" />
      <mass
        value="0.042971" />
      <inertia
        ixx="1.9341E-06"
        ixy="-6.1647E-12"
        ixz="3.4221E-13"
        iyy="1.6622E-05"
        iyz="-1.4195E-13"
        izz="1.7525E-05" />
    </inertial>
    <visual>
      <origin
        xyz="0 0 0"
        rpy="0 0 0" />
      <geometry>
        <mesh
          filename="meshes_obj/RL3.obj" />
      </geometry>
      <material
        name="">
        <color
          rgba="0.86667 0.9098 1 1" />
      </material>
    </visual>
    <collision>
      <origin
        xyz="0 0 0"
        rpy="0 0 0" />
      <geometry>
        <mesh
          filename="meshes_obj/RL3.obj" />
      </geometry>
    </collision>
  </link>
  <joint
    name="joint8"
    type="revolute">
    <origin
      xyz="0.06 0 0"
      rpy="0 0 0.78605" />
    <parent
      link="RL2" />
    <child
      link="RL3" />
    <axis
      xyz="0 0 1" />
    <limit
      lower="-1.57"
      upper="1.57"
      effort="5"
      velocity="2" />
  </joint>
</robot>